<?xml version="1.0" ?>
<!-- =================================================================================== -->
<!-- |    This document was autogenerated by xacro from ur5e_joint_limited_robotiq_2f_85.urdf.xacro | -->
<!-- |    EDITING THIS FILE BY HAND IS NOT RECOMMENDED                                 | -->
<!-- =================================================================================== -->
<robot name="ur5e_joint_limited_robotiq_2f_85" xmlns:xacro="http://ros.org/wiki/xacro">
  <gazebo>
    <plugin filename="libgazebo_ros_control.so" name="ros_control">
      <!--robotNamespace>/</robotNamespace-->
      <!--robotSimType>gazebo_ros_control/DefaultRobotHWSim</robotSimType-->
    </plugin>
    <!--
    <plugin name="gazebo_ros_power_monitor_controller" filename="libgazebo_ros_power_monitor.so">
      <alwaysOn>true</alwaysOn>
      <updateRate>1.0</updateRate>
      <timeout>5</timeout>
      <powerStateTopic>power_state</powerStateTopic>
      <powerStateRate>10.0</powerStateRate>
      <fullChargeCapacity>87.78</fullChargeCapacity>     
      <dischargeRate>-474</dischargeRate>
      <chargeRate>525</chargeRate>
      <dischargeVoltage>15.52</dischargeVoltage>
      <chargeVoltage>16.41</chargeVoltage>
    </plugin>
-->
  </gazebo>
  <!--property name="shoulder_height" value="0.089159" /-->
  <!--property name="shoulder_offset" value="0.13585" /-->
  <!-- shoulder_offset - elbow_offset + wrist_1_length = 0.10915 -->
  <!--property name="upper_arm_length" value="0.42500" /-->
  <!--property name="elbow_offset" value="0.1197" /-->
  <!-- CAD measured -->
  <!--property name="forearm_length" value="0.39225" /-->
  <!--property name="wrist_1_length" value="0.093" /-->
  <!-- CAD measured -->
  <!--property name="wrist_2_length" value="0.09465" /-->
  <!-- In CAD this distance is 0.930, but in the spec it is 0.09465 -->
  <!--property name="wrist_3_length" value="0.0823" /-->
  <!-- manually measured -->
  <link name="base_link">
    <visual>
      <geometry>
        <mesh filename="package://ur_e_description/meshes/ur5e/visual/base.dae"/>
      </geometry>
      <material name="LightGrey">
        <color rgba="0.7 0.7 0.7 1.0"/>
      </material>
    </visual>
    <collision>
      <geometry>
        <mesh filename="package://ur_e_description/meshes/ur5e/collision/base.stl"/>
      </geometry>
    </collision>
    <inertial>
      <mass value="4.0"/>
      <origin rpy="0 0 0" xyz="0.0 0.0 0.0"/>
      <inertia ixx="0.00443333156" ixy="0.0" ixz="0.0" iyy="0.00443333156" iyz="0.0" izz="0.0072"/>
    </inertial>
  </link>
  <joint name="shoulder_pan_joint" type="revolute">
    <parent link="base_link"/>
    <child link="shoulder_link"/>
    <origin rpy="0.0 0.0 0.0" xyz="0.0 0.0 0.163"/>
    <axis xyz="0 0 1"/>
    <limit effort="150.0" lower="-6.28318530718" upper="6.28318530718" velocity="3.14"/>
    <dynamics damping="0.0" friction="0.0"/>
  </joint>
  <link name="shoulder_link">
    <visual>
      <geometry>
        <mesh filename="package://ur_e_description/meshes/ur5e/visual/shoulder.dae"/>
      </geometry>
      <material name="LightGrey">
        <color rgba="0.7 0.7 0.7 1.0"/>
      </material>
    </visual>
    <collision>
      <geometry>
        <mesh filename="package://ur_e_description/meshes/ur5e/collision/shoulder.stl"/>
      </geometry>
    </collision>
    <inertial>
      <mass value="3.7"/>
      <origin rpy="0 0 0" xyz="0.0 0.0 0.0"/>
      <inertia ixx="0.010267495893" ixy="0.0" ixz="0.0" iyy="0.010267495893" iyz="0.0" izz="0.00666"/>
    </inertial>
  </link>
  <joint name="shoulder_lift_joint" type="revolute">
    <parent link="shoulder_link"/>
    <child link="upper_arm_link"/>
    <origin rpy="0.0 1.57079632679 0.0" xyz="0.0 0.138 0.0"/>
    <axis xyz="0 1 0"/>
    <limit effort="150.0" lower="-6.28318530718" upper="6.28318530718" velocity="3.14"/>
    <dynamics damping="0.0" friction="0.0"/>
  </joint>
  <link name="upper_arm_link">
    <visual>
      <geometry>
        <mesh filename="package://ur_e_description/meshes/ur5e/visual/upperarm.dae"/>
      </geometry>
      <material name="LightGrey">
        <color rgba="0.7 0.7 0.7 1.0"/>
      </material>
    </visual>
    <collision>
      <geometry>
        <mesh filename="package://ur_e_description/meshes/ur5e/collision/upperarm.stl"/>
      </geometry>
    </collision>
    <inertial>
      <mass value="8.393"/>
      <origin rpy="0 0 0" xyz="0.0 0.0 0.2125"/>
      <inertia ixx="0.133885781862" ixy="0.0" ixz="0.0" iyy="0.133885781862" iyz="0.0" izz="0.0151074"/>
    </inertial>
  </link>
  <joint name="elbow_joint" type="revolute">
    <parent link="upper_arm_link"/>
    <child link="forearm_link"/>
    <origin rpy="0.0 0.0 0.0" xyz="0.0 -0.131 0.425"/>
    <axis xyz="0 1 0"/>
    <limit effort="150.0" lower="-3.14159265359" upper="3.14159265359" velocity="3.14"/>
    <dynamics damping="0.0" friction="0.0"/>
  </joint>
  <link name="forearm_link">
    <visual>
      <geometry>
        <mesh filename="package://ur_e_description/meshes/ur5e/visual/forearm.dae"/>
      </geometry>
      <material name="LightGrey">
        <color rgba="0.7 0.7 0.7 1.0"/>
      </material>
    </visual>
    <collision>
      <geometry>
        <mesh filename="package://ur_e_description/meshes/ur5e/collision/forearm.stl"/>
      </geometry>
    </collision>
    <inertial>
      <mass value="2.275"/>
      <origin rpy="0 0 0" xyz="0.0 0.0 0.196"/>
      <inertia ixx="0.0311796208615" ixy="0.0" ixz="0.0" iyy="0.0311796208615" iyz="0.0" izz="0.004095"/>
    </inertial>
  </link>
  <joint name="wrist_1_joint" type="revolute">
    <parent link="forearm_link"/>
    <child link="wrist_1_link"/>
    <origin rpy="0.0 1.57079632679 0.0" xyz="0.0 0.0 0.392"/>
    <axis xyz="0 1 0"/>
    <limit effort="28.0" lower="-6.28318530718" upper="6.28318530718" velocity="6.28"/>
    <dynamics damping="0.0" friction="0.0"/>
  </joint>
  <link name="wrist_1_link">
    <visual>
      <geometry>
        <mesh filename="package://ur_e_description/meshes/ur5e/visual/wrist1.dae"/>
      </geometry>
      <material name="LightGrey">
        <color rgba="0.7 0.7 0.7 1.0"/>
      </material>
    </visual>
    <collision>
      <geometry>
        <mesh filename="package://ur_e_description/meshes/ur5e/collision/wrist1.stl"/>
      </geometry>
    </collision>
    <inertial>
      <mass value="1.219"/>
      <origin rpy="0 0 0" xyz="0.0 0.127 0.0"/>
      <inertia ixx="0.00255989897604" ixy="0.0" ixz="0.0" iyy="0.00255989897604" iyz="0.0" izz="0.0021942"/>
    </inertial>
  </link>
  <joint name="wrist_2_joint" type="revolute">
    <parent link="wrist_1_link"/>
    <child link="wrist_2_link"/>
    <origin rpy="0.0 0.0 0.0" xyz="0.0 0.127 0.0"/>
    <axis xyz="0 0 1"/>
    <limit effort="28.0" lower="-6.28318530718" upper="6.28318530718" velocity="6.28"/>
    <dynamics damping="0.0" friction="0.0"/>
  </joint>
  <link name="wrist_2_link">
    <visual>
      <geometry>
        <mesh filename="package://ur_e_description/meshes/ur5e/visual/wrist2.dae"/>
      </geometry>
      <material name="LightGrey">
        <color rgba="0.7 0.7 0.7 1.0"/>
      </material>
    </visual>
    <collision>
      <geometry>
        <mesh filename="package://ur_e_description/meshes/ur5e/collision/wrist2.stl"/>
      </geometry>
    </collision>
    <inertial>
      <mass value="1.219"/>
      <origin rpy="0 0 0" xyz="0.0 0.0 0.1"/>
      <inertia ixx="0.00255989897604" ixy="0.0" ixz="0.0" iyy="0.00255989897604" iyz="0.0" izz="0.0021942"/>
    </inertial>
  </link>
  <joint name="wrist_3_joint" type="revolute">
    <parent link="wrist_2_link"/>
    <child link="wrist_3_link"/>
    <origin rpy="0.0 0.0 0.0" xyz="0.0 0.0 0.1"/>
    <axis xyz="0 1 0"/>
    <limit effort="28.0" lower="-6.28318530718" upper="6.28318530718" velocity="6.28"/>
    <dynamics damping="0.0" friction="0.0"/>
  </joint>
  <link name="wrist_3_link">
    <visual>
      <geometry>
        <mesh filename="package://ur_e_description/meshes/ur5e/visual/wrist3.dae"/>
      </geometry>
      <material name="LightGrey">
        <color rgba="0.7 0.7 0.7 1.0"/>
      </material>
    </visual>
    <collision>
      <geometry>
        <mesh filename="package://ur_e_description/meshes/ur5e/collision/wrist3.stl"/>
      </geometry>
    </collision>
    <inertial>
      <mass value="0.1879"/>
      <origin rpy="1.57079632679 0 0" xyz="0.0 0.0771 0.0"/>
      <inertia ixx="9.89041005217e-05" ixy="0.0" ixz="0.0" iyy="9.89041005217e-05" iyz="0.0" izz="0.0001321171875"/>
    </inertial>
  </link>
  <joint name="ee_fixed_joint" type="fixed">
    <parent link="wrist_3_link"/>
    <child link="ee_link"/>
    <origin rpy="0.0 0.0 1.57079632679" xyz="0.0 0.1 0.0"/>
  </joint>
  <link name="ee_link">
    <collision>
      <geometry>
        <box size="0.01 0.01 0.01"/>
      </geometry>
      <origin rpy="0 0 0" xyz="-0.01 0 0"/>
    </collision>
  </link>
  <transmission name="shoulder_pan_trans">
    <type>transmission_interface/SimpleTransmission</type>
    <joint name="shoulder_pan_joint">
      <hardwareInterface>hardware_interface/PositionJointInterface</hardwareInterface>
    </joint>
    <actuator name="shoulder_pan_motor">
      <mechanicalReduction>1</mechanicalReduction>
    </actuator>
  </transmission>
  <transmission name="shoulder_lift_trans">
    <type>transmission_interface/SimpleTransmission</type>
    <joint name="shoulder_lift_joint">
      <hardwareInterface>hardware_interface/PositionJointInterface</hardwareInterface>
    </joint>
    <actuator name="shoulder_lift_motor">
      <mechanicalReduction>1</mechanicalReduction>
    </actuator>
  </transmission>
  <transmission name="elbow_trans">
    <type>transmission_interface/SimpleTransmission</type>
    <joint name="elbow_joint">
      <hardwareInterface>hardware_interface/PositionJointInterface</hardwareInterface>
    </joint>
    <actuator name="elbow_motor">
      <mechanicalReduction>1</mechanicalReduction>
    </actuator>
  </transmission>
  <transmission name="wrist_1_trans">
    <type>transmission_interface/SimpleTransmission</type>
    <joint name="wrist_1_joint">
      <hardwareInterface>hardware_interface/PositionJointInterface</hardwareInterface>
    </joint>
    <actuator name="wrist_1_motor">
      <mechanicalReduction>1</mechanicalReduction>
    </actuator>
  </transmission>
  <transmission name="wrist_2_trans">
    <type>transmission_interface/SimpleTransmission</type>
    <joint name="wrist_2_joint">
      <hardwareInterface>hardware_interface/PositionJointInterface</hardwareInterface>
    </joint>
    <actuator name="wrist_2_motor">
      <mechanicalReduction>1</mechanicalReduction>
    </actuator>
  </transmission>
  <transmission name="wrist_3_trans">
    <type>transmission_interface/SimpleTransmission</type>
    <joint name="wrist_3_joint">
      <hardwareInterface>hardware_interface/PositionJointInterface</hardwareInterface>
    </joint>
    <actuator name="wrist_3_motor">
      <mechanicalReduction>1</mechanicalReduction>
    </actuator>
  </transmission>
  <gazebo reference="shoulder_link">
    <selfCollide>true</selfCollide>
  </gazebo>
  <gazebo reference="upper_arm_link">
    <selfCollide>true</selfCollide>
  </gazebo>
  <gazebo reference="forearm_link">
    <selfCollide>true</selfCollide>
  </gazebo>
  <gazebo reference="wrist_1_link">
    <selfCollide>true</selfCollide>
  </gazebo>
  <gazebo reference="wrist_3_link">
    <selfCollide>true</selfCollide>
  </gazebo>
  <gazebo reference="wrist_2_link">
    <selfCollide>true</selfCollide>
  </gazebo>
  <gazebo reference="ee_link">
    <selfCollide>true</selfCollide>
  </gazebo>
  <!-- ROS base_link to UR 'Base' Coordinates transform -->
  <link name="base"/>
  <joint name="base_link-base_fixed_joint" type="fixed">
    <!-- NOTE: this rotation is only needed as long as base_link itself is
                 not corrected wrt the real robot (ie: rotated over 180
                 degrees)
      -->
    <origin rpy="0 0 -3.14159265359" xyz="0 0 0"/>
    <parent link="base_link"/>
    <child link="base"/>
  </joint>
  <!-- Frame coincident with all-zeros TCP on UR controller -->
  <link name="tool0"/>
  <joint name="wrist_3_link-tool0_fixed_joint" type="fixed">
    <origin rpy="-1.57079632679 0 0" xyz="0 0.1 0"/>
    <parent link="wrist_3_link"/>
    <child link="tool0"/>
  </joint>
  <link name="realsense_camera_mount_link">
    <inertial>
      <origin rpy="0 0 0" xyz="-0.033226 -0.0065621 -0.0028938"/>
      <mass value="0.14272"/>
      <inertia ixx="0" ixy="0" ixz="0" iyy="0" iyz="0" izz="0"/>
    </inertial>
    <visual>
      <origin rpy="0 0 0" xyz="0 0 0"/>
      <geometry>
        <mesh filename="package://robotiq_2f_85_full/meshes/realsense_camera_link.STL"/>
      </geometry>
      <material name="">
        <color rgba="0.79216 0.81961 0.93333 1"/>
      </material>
    </visual>
    <collision>
      <origin rpy="0 0 0" xyz="0 0 0"/>
      <geometry>
        <mesh filename="package://robotiq_2f_85_full/meshes/realsense_camera_link.STL"/>
      </geometry>
    </collision>
  </link>
  <link name="millibar_adapter_robot_link">
    <inertial>
      <origin rpy="0 0 0" xyz="-0.0184274406708507 -0.00637681665375706 -0.053327869751534"/>
      <mass value="0.0726726298269008"/>
      <inertia ixx="9.38320322471287E-06" ixy="6.46884881109961E-08" ixz="1.85110039132892E-07" iyy="9.26662239699562E-06" iyz="-8.03404544445827E-07" izz="1.17418969978238E-06"/>
    </inertial>
    <visual>
      <origin rpy="0 0 0" xyz="0 0 0"/>
      <geometry>
        <mesh filename="package://robotiq_2f_85_full/meshes/millibar_adapter_robot_link.STL"/>
      </geometry>
      <material name="">
        <color rgba="0.776470588235294 0.756862745098039 0.737254901960784 1"/>
      </material>
    </visual>
    <collision>
      <origin rpy="0 0 0" xyz="0 0 0"/>
      <geometry>
        <mesh filename="package://robotiq_2f_85_full/meshes/millibar_adapter_robot_link.STL"/>
      </geometry>
    </collision>
  </link>
  <joint name="realsense_adapter_to_millibar_adapter_robot_joint" type="fixed">
    <origin rpy="2.7059E-16 0.7854 -3.1416" xyz="-0.10267 0.0074988 0.0034576"/>
    <parent link="realsense_camera_mount_link"/>
    <child link="millibar_adapter_robot_link"/>
    <axis xyz="0 0 0"/>
  </joint>
  <link name="millibar_adapter_gripper_link">
    <inertial>
      <origin rpy="0 0 0" xyz="0.000339767777517416 0.000413108059073474 -0.00316348991929165"/>
      <mass value="0.0615924087528081"/>
      <inertia ixx="2.6820752422346E-06" ixy="-1.20350331596028E-07" ixz="6.48740657216567E-08" iyy="6.10831607617094E-07" iyz="1.12024733686772E-06" izz="2.0851827265745E-06"/>
    </inertial>
    <visual>
      <origin rpy="0 0 0" xyz="0 0 0"/>
      <geometry>
        <mesh filename="package://robotiq_2f_85_full/meshes/millibar_adapter_gripper_link.STL"/>
      </geometry>
      <material name="">
        <color rgba="0.647058823529412 0.619607843137255 0.588235294117647 1"/>
      </material>
    </visual>
    <collision>
      <origin rpy="0 0 0" xyz="0 0 0"/>
      <geometry>
        <mesh filename="package://robotiq_2f_85_full/meshes/millibar_adapter_gripper_link.STL"/>
      </geometry>
    </collision>
  </link>
  <joint name="millibar_adapter_robot_to_millibar_adapter_gripper_joint" type="fixed">
    <origin rpy="0 -1.5707963267949 0" xyz="-0.0163169066859088 -0.019447 -0.051496847997168"/>
    <parent link="millibar_adapter_robot_link"/>
    <child link="millibar_adapter_gripper_link"/>
    <axis xyz="0 0 0"/>
  </joint>
  <link name="tcpip_adapter_link">
    <inertial>
      <origin rpy="0 0 0" xyz="-0.00136790557020363 8.53247449260908E-05 -0.00126580798615109"/>
      <mass value="0.0395985753458659"/>
      <inertia ixx="0" ixy="0" ixz="0" iyy="0" iyz="0" izz="0"/>
    </inertial>
    <visual>
      <origin rpy="0 0 0" xyz="0 0 0"/>
      <geometry>
        <mesh filename="package://robotiq_2f_85_full/meshes/tcpip_adapter_link.STL"/>
      </geometry>
      <material name="">
        <color rgba="0.796078431372549 0.823529411764706 0.937254901960784 1"/>
      </material>
    </visual>
    <collision>
      <origin rpy="0 0 0" xyz="0 0 0"/>
      <geometry>
        <mesh filename="package://robotiq_2f_85_full/meshes/tcpip_adapter_link.STL"/>
      </geometry>
    </collision>
  </link>
  <joint name="millibar_adapter_gripper_to_tcpip_adapter_joint" type="fixed">
    <origin rpy="1.5707963267949 2.77555756156289E-16 1.97215226305253E-31" xyz="0 -0.019 0"/>
    <parent link="millibar_adapter_gripper_link"/>
    <child link="tcpip_adapter_link"/>
    <axis xyz="0 0 0"/>
  </joint>
  <link name="robotiq_2f_85_body_link">
    <inertial>
      <origin rpy="0 0 0" xyz="0.00438949381849164 0.0105529993808305 0.199500811777213"/>
      <mass value="0.234330881455963"/>
      <inertia ixx="9.20072404929443E-06" ixy="-9.55166293501857E-13" ixz="1.00683829390664E-10" iyy="9.34710914818527E-06" iyz="8.52705980009592E-08" izz="1.60641773920936E-07"/>
    </inertial>
    <visual>
      <origin rpy="0 0 0" xyz="0 0 0"/>
      <geometry>
        <mesh filename="package://robotiq_2f_85_full/meshes/robotiq_2f_85_body_link.STL"/>
      </geometry>
      <material name="">
        <color rgba="0.792156862745098 0.819607843137255 0.933333333333333 1"/>
      </material>
    </visual>
    <collision>
      <origin rpy="0 0 0" xyz="0 0 0"/>
      <geometry>
        <mesh filename="package://robotiq_2f_85_full/meshes/robotiq_2f_85_body_link.STL"/>
      </geometry>
    </collision>
  </link>
  <joint name="tcpip_adapter_to_robotiq_2f_85_body_joint" type="fixed">
    <origin rpy="-6.93889390390723E-16 -5.52350545074437E-28 -7.95752352900081E-13" xyz="-0.00438896412532407 -0.0105415302656592 -0.162248066837809"/>
    <parent link="tcpip_adapter_link"/>
    <child link="robotiq_2f_85_body_link"/>
    <axis xyz="0 0 0"/>
  </joint>
  <link name="robotiq_2f_85_left_finger_link">
    <inertial>
      <origin rpy="0 0 0" xyz="0.00418730309969449 0.0317563630844434 0.255882424968551"/>
      <mass value="0.038905376961614"/>
      <inertia ixx="1.68705018386956E-05" ixy="-9.67455762819946E-13" ixz="-2.93070106557132E-06" iyy="2.40910213017045E-05" iyz="3.97452007549286E-13" izz="7.22051946300933E-06"/>
    </inertial>
    <visual>
      <origin rpy="0 0 0" xyz="0 0 0"/>
      <geometry>
        <mesh filename="package://robotiq_2f_85_full/meshes/robotiq_2f_85_left_finger_link.STL"/>
      </geometry>
      <material name="">
        <color rgba="0.792156862745098 0.819607843137255 0.933333333333333 1"/>
      </material>
    </visual>
    <collision>
      <origin rpy="0 0 0" xyz="0 0 0"/>
      <geometry>
        <mesh filename="package://robotiq_2f_85_full/meshes/robotiq_2f_85_left_finger_link.STL"/>
      </geometry>
    </collision>
  </link>
  <joint name="robotiq_2f_85_body_to_robotiq_2f_85_left_finger_joint" type="fixed">
    <origin rpy="0 0 -3.14159265358979" xyz="0.0614081599849013 0.0421978920004752 0"/>
    <parent link="robotiq_2f_85_body_link"/>
    <child link="robotiq_2f_85_left_finger_link"/>
    <axis xyz="0 0 0"/>
  </joint>
  <link name="robotiq_2f_85_right_finger_link">
    <inertial>
      <origin rpy="0 0 0" xyz="0.109851081060267 0.0317563608841004 0.255882429187002"/>
      <mass value="0.0389053769573109"/>
      <inertia ixx="1.68705133963097E-05" ixy="-9.16643854665332E-13" ixz="2.93071184589305E-06" iyy="2.40910344039002E-05" iyz="-1.0779768214657E-12" izz="7.22052100759103E-06"/>
    </inertial>
    <visual>
      <origin rpy="0 0 0" xyz="0 0 0"/>
      <geometry>
        <mesh filename="package://robotiq_2f_85_full/meshes/robotiq_2f_85_right_finger_link.STL"/>
      </geometry>
      <material name="">
        <color rgba="0.792156862745098 0.819607843137255 0.933333333333333 1"/>
      </material>
    </visual>
    <collision>
      <origin rpy="0 0 0" xyz="0 0 0"/>
      <geometry>
        <mesh filename="package://robotiq_2f_85_full/meshes/robotiq_2f_85_right_finger_link.STL"/>
      </geometry>
    </collision>
  </link>
  <joint name="robotiq_2f_85_body_to_robotiq_2f_85_right_finger_joint" type="fixed">
    <origin rpy="0 0 -3.14159265358979" xyz="0.0614081599849013 0.0421978920004752 0"/>
    <parent link="robotiq_2f_85_body_link"/>
    <child link="robotiq_2f_85_right_finger_link"/>
    <axis xyz="0 0 0"/>
  </joint>
  <link name="tcp_link"/>
  <joint name="tcpip_adapter_to_tcp_joint" type="fixed">
    <origin rpy="0 0 0" xyz="-0.0 0.0 0.14"/>
    <parent link="tcpip_adapter_link"/>
    <child link="tcp_link"/>
    <axis xyz="0 0 0"/>
  </joint>
  <link name="realsense_camera_link">
    <visual>
      <origin rpy="0 0 0" xyz="0 0 0"/>
      <geometry>
        <box size="0.09 0.025 0.025"/>
      </geometry>
    </visual>
  </link>
  <joint name="realsense_camera_adapter_to_realsense_camera_joint" type="fixed">
    <origin rpy="0 0.7854 0" xyz="0.00625 0.008125 0.04375"/>
    <parent link="realsense_camera_mount_link"/>
    <child link="realsense_camera_link"/>
    <axis xyz="0 0 0"/>
  </joint>
  <joint name="robotiq_85_adapters_joint" type="fixed">
    <parent link="tool0"/>
    <child link="realsense_camera_mount_link"/>
    <origin rpy="1.5707 0.0 -0.785" xyz="0.0235 -0.0535 0.0115"/>
  </joint>
  <!-- world -->
  <link name="world"/>
  <!-- world to robot joint -->
  <joint name="world_joint" type="fixed">
    <parent link="world"/>
    <child link="base_link"/>
    <origin rpy="0.0 0.0 0.0" xyz="0.0 0.0 0.0"/>
  </joint>
</robot>
